<?xml version="1.0" encoding="utf-8"?>
<!-- This URDF was automatically created by SolidWorks to URDF Exporter! Originally created by Stephen Brawner (brawner@gmail.com) 
     Commit Version: 1.6.0-4-g7f85cfe  Build Version: 1.6.7995.38578
     For more information, please see http://wiki.ros.org/sw_urdf_exporter -->
<robot
  name="wheelchair">
  <link
    name="base_link">
    <inertial>
      <origin
        xyz="-0.0776996596788162 0.234803664226308 0.600991954381718"
        rpy="0 0 0" />
      <mass
        value="98.7152301309315" />
      <inertia
        ixx="3.96388155541818"
        ixy="1.14964171081817"
        ixz="0.00612644036675662"
        iyy="5.29576019975943"
        iyz="-0.00406848391148331"
        izz="5.19553156553935" />
    </inertial>
    <visual>
      <origin
        xyz="0 0 0"
        rpy="0 0 0" />
      <geometry>
        <mesh
          filename="package://wheelchair/meshes/base_link.STL" />
      </geometry>
      <material
        name="">
        <color
          rgba="0.792156862745098 0.819607843137255 0.933333333333333 1" />
      </material>
    </visual>
    <collision>
      <origin
        xyz="0 0 0"
        rpy="0 0 0" />
      <geometry>
        <mesh
          filename="package://wheelchair/meshes/base_link.STL" />
      </geometry>
    </collision>
  </link>
  <link
    name="laser_link">
    <inertial>
      <origin
        xyz="-0.00034387 0.036297 3.2869E-06"
        rpy="0 0 0" />
      <mass
        value="0.60561" />
      <inertia
        ixx="0.00066704"
        ixy="1.8129E-06"
        ixz="1.7526E-11"
        iyy="0.00080407"
        iyz="6.6764E-08"
        izz="0.00067092" />
    </inertial>
    <visual>
      <origin
        xyz="0 0 0"
        rpy="0 0 0" />
      <geometry>
        <mesh
          filename="package://wheelchair/meshes/laser_link.STL" />
      </geometry>
      <material
        name="">
        <color
          rgba="0.79216 0.81961 0.93333 1" />
      </material>
    </visual>
    <collision>
      <origin
        xyz="0 0 0"
        rpy="0 0 0" />
      <geometry>
        <mesh
          filename="package://wheelchair/meshes/laser_link.STL" />
      </geometry>
    </collision>
  </link>
  <joint
    name="laser_joint"
    type="fixed">
    <origin
      xyz="-0.29009 -0.60303 1.1909"
      rpy="1.5708 0 3.1416" />
    <parent
      link="base_link" />
    <child
      link="laser_link" />
    <axis
      xyz="0 0 0" />
  </joint>
  <link
    name="imu_link">
    <inertial>
      <origin
        xyz="0.022 0.0051671 0.012"
        rpy="0 0 0" />
      <mass
        value="0.0094947" />
      <inertia
        ixx="5.8167E-07"
        ixy="1.4095E-22"
        ixz="8.9443E-23"
        iyy="2.0583E-06"
        iyz="-2.353E-23"
        izz="1.7103E-06" />
    </inertial>
    <visual>
      <origin
        xyz="0 0 0"
        rpy="0 0 0" />
      <geometry>
        <mesh
          filename="package://wheelchair/meshes/imu_link.STL" />
      </geometry>
      <material
        name="">
        <color
          rgba="0.79216 0.81961 0.93333 1" />
      </material>
    </visual>
    <collision>
      <origin
        xyz="0 0 0"
        rpy="0 0 0" />
      <geometry>
        <mesh
          filename="package://wheelchair/meshes/imu_link.STL" />
      </geometry>
    </collision>
  </link>
  <joint
    name="imu_joint"
    type="fixed">
    <origin
      xyz="0.075361 -0.88946 0.45753"
      rpy="1.5708 0 0" />
    <parent
      link="base_link" />
    <child
      link="imu_link" />
    <axis
      xyz="0 0 0" />
  </joint>
  <link
    name="wheel_back_one">
    <inertial>
      <origin
        xyz="-0.04 -1.1102E-16 3.4903E-15"
        rpy="0 0 0" />
      <mass
        value="1.7338" />
      <inertia
        ixx="0.010388"
        ixy="1.7449E-18"
        ixz="9.5785E-19"
        iyy="0.0060348"
        iyz="3.9031E-18"
        izz="0.0060348" />
    </inertial>
    <visual>
      <origin
        xyz="0 0 0"
        rpy="0 0 0" />
      <geometry>
        <mesh
          filename="package://wheelchair/meshes/wheel_back_one.STL" />
      </geometry>
      <material
        name="">
        <color
          rgba="0.25098 0.25098 0.25098 1" />
      </material>
    </visual>
    <collision>
      <origin
        xyz="0 0 0"
        rpy="0 0 0" />
      <geometry>
        <mesh
          filename="package://wheelchair/meshes/wheel_back_one.STL" />
      </geometry>
    </collision>
  </link>
  <joint
    name="wheel_bo"
    type="continuous">
    <origin
      xyz="-0.22501 -0.8357 -0.074094"
      rpy="2.869 0 1.5708" />
    <parent
      link="base_link" />
    <child
      link="wheel_back_one" />
    <axis
      xyz="1 0 0" />
  </joint>
  <link
    name="wheel_back_two">
    <inertial>
      <origin
        xyz="0.04 2.498E-16 -1.3878E-16"
        rpy="0 0 0" />
      <mass
        value="1.7338" />
      <inertia
        ixx="0.010388"
        ixy="-8.8954E-19"
        ixz="-1.1797E-18"
        iyy="0.0060348"
        iyz="4.7705E-18"
        izz="0.0060348" />
    </inertial>
    <visual>
      <origin
        xyz="0 0 0"
        rpy="0 0 0" />
      <geometry>
        <mesh
          filename="package://wheelchair/meshes/wheel_back_two.STL" />
      </geometry>
      <material
        name="">
        <color
          rgba="0.25098 0.25098 0.25098 1" />
      </material>
    </visual>
    <collision>
      <origin
        xyz="0 0 0"
        rpy="0 0 0" />
      <geometry>
        <mesh
          filename="package://wheelchair/meshes/wheel_back_two.STL" />
      </geometry>
    </collision>
  </link>
  <joint
    name="wheel_bt"
    type="continuous">
    <origin
      xyz="-0.22501 -0.2843 -0.074094"
      rpy="-2.5998 0 -1.5708" />
    <parent
      link="base_link" />
    <child
      link="wheel_back_two" />
    <axis
      xyz="1 0 0" />
  </joint>
  <link
    name="wheel_front_one">
    <inertial>
      <origin
        xyz="-0.035 1.2629E-15 -2.0817E-15"
        rpy="0 0 0" />
      <mass
        value="1.0384" />
      <inertia
        ixx="0.0038781"
        ixy="1.0574E-17"
        ixz="6.822E-18"
        iyy="0.0023093"
        iyz="3.2861E-17"
        izz="0.0023093" />
    </inertial>
    <visual>
      <origin
        xyz="0 0 0"
        rpy="0 0 0" />
      <geometry>
        <mesh
          filename="package://wheelchair/meshes/wheel_front_one.STL" />
      </geometry>
      <material
        name="">
        <color
          rgba="0.25098 0.25098 0.25098 1" />
      </material>
    </visual>
    <collision>
      <origin
        xyz="0 0 0"
        rpy="0 0 0" />
      <geometry>
        <mesh
          filename="package://wheelchair/meshes/wheel_front_one.STL" />
      </geometry>
    </collision>
  </link>
  <joint
    name="wheel_fo"
    type="continuous">
    <origin
      xyz="0.17499 -0.293 -0.094094"
      rpy="1.5708 0 1.5708" />
    <parent
      link="base_link" />
    <child
      link="wheel_front_one" />
    <axis
      xyz="1 0 0" />
  </joint>
  <link
    name="wheel_front_two">
    <inertial>
      <origin
        xyz="0 0 0"
        rpy="0 0 0" />
      <mass
        value="0" />
      <inertia
        ixx="0"
        ixy="0"
        ixz="0"
        iyy="0"
        iyz="0"
        izz="0" />
    </inertial>
    <visual>
      <origin
        xyz="0 0 0"
        rpy="0 0 0" />
      <geometry>
        <mesh
          filename="package://wheelchair/meshes/wheel_front_two.STL" />
      </geometry>
      <material
        name="">
        <color
          rgba="1 1 1 1" />
      </material>
    </visual>
    <collision>
      <origin
        xyz="0 0 0"
        rpy="0 0 0" />
      <geometry>
        <mesh
          filename="package://wheelchair/meshes/wheel_front_two.STL" />
      </geometry>
    </collision>
  </link>
  <joint
    name="wheel_ft"
    type="continuous">
    <origin
      xyz="0.17499 -0.837 -0.094094"
      rpy="-2.3112 0 -1.5708" />
    <parent
      link="base_link" />
    <child
      link="wheel_front_two" />
    <axis
      xyz="1 0 0" />
  </joint>
</robot>